{"uuid": "b54f6e99-67ed-41da-b944-5395cdd6f07e", "children": ["04843999-07ee-4ec8-97c2-c53a54fc28ee"], "befores": [{"name": "driver", "status": "skipped", "statusDetails": {"message": "Skipped: Не удалось подключиться к android Appium серверу после 3 попыток: Message: An unknown server-side error occurred while processing the command. Original error: The instrumentation process cannot be initialized within 30000ms timeout. Make sure the application under test does not crash and investigate the logcat output. You could also try to increase the value of 'uiautomator2ServerLaunchTimeout' capability\nStacktrace:\nUnknownError: An unknown server-side error occurred while processing the command. Original error: The instrumentation process cannot be initialized within 30000ms timeout. Make sure the application under test does not crash and investigate the logcat output. You could also try to increase the value of 'uiautomator2ServerLaunchTimeout' capability\n    at getResponseForW3CError (/usr/local/lib/node_modules/appium/node_modules/@appium/base-driver/lib/protocol/errors.js:1145:9)\n    at asyncHandler (/usr/local/lib/node_modules/appium/node_modules/@appium/base-driver/lib/protocol/protocol.js:485:57)\n", "trace": "  File \"/Users/a00059362/Desktop/Новая папка/onlineduken/.venv/lib/python3.13/site-packages/pluggy/_callers.py\", line 38, in run_old_style_hookwrapper\n    res = yield\n          ^^^^^\n  File \"/Users/a00059362/Desktop/Новая папка/onlineduken/.venv/lib/python3.13/site-packages/pluggy/_callers.py\", line 139, in _multicall\n    teardown.throw(exception)\n    ~~~~~~~~~~~~~~^^^^^^^^^^^\n  File \"/Users/a00059362/Desktop/Новая папка/onlineduken/.venv/lib/python3.13/site-packages/_pytest/setuponly.py\", line 36, in pytest_fixture_setup\n    return (yield)\n            ^^^^^\n  File \"/Users/a00059362/Desktop/Новая папка/onlineduken/.venv/lib/python3.13/site-packages/pluggy/_callers.py\", line 121, in _multicall\n    res = hook_impl.function(*args)\n  File \"/Users/a00059362/Desktop/Новая папка/onlineduken/.venv/lib/python3.13/site-packages/_pytest/fixtures.py\", line 1196, in pytest_fixture_setup\n    result = call_fixture_func(fixturefunc, request, kwargs)\n  File \"/Users/a00059362/Desktop/Новая папка/onlineduken/.venv/lib/python3.13/site-packages/_pytest/fixtures.py\", line 923, in call_fixture_func\n    fixture_result = next(generator)\n  File \"/Users/a00059362/Desktop/Новая папка/onlineduken/conftest.py\", line 307, in driver\n    pytest.skip(f\"Не удалось подключиться к {platform} Appium серверу после {attempts} попыток: {e}\")\n    ~~~~~~~~~~~^^^^^^^^^^^^^^^^^^^^^^^^^^^^^^^^^^^^^^^^^^^^^^^^^^^^^^^^^^^^^^^^^^^^^^^^^^^^^^^^^^^^^^\n  File \"/Users/a00059362/Desktop/Новая папка/onlineduken/.venv/lib/python3.13/site-packages/_pytest/outcomes.py\", line 159, in skip\n    raise Skipped(msg=reason, allow_module_level=allow_module_level)\n"}, "start": 1759832810991, "stop": 1759833124739}], "start": 1759832810991, "stop": 1759833139105}